Workbook
Name _Hlk99922360: SubclassAspects!$BE$57

Sheet Sheet1
C1: Name: | D1: Scout
C2: Tier: | D2: 1
C3: Base: | D3: Archer
C4: Code: | D4: 2
C5: Requirements:
C6: =IF(SubclassAspects!C13>0,"Dexterity ", "") -> Dexterity | D6: =IF(SubclassAspects!C13>0,SubclassAspects!C13) -> 58 | E6: =IF(SubclassAspects!C17>0,"Charisma ", "") -> Charisma | F6: =IF(SubclassAspects!C17>0,SubclassAspects!C17, "") -> 58
C7: =IF(SubclassAspects!C14>0,"Dexterity ","") | D7: =IF(SubclassAspects!C14>0,SubclassAspects!C14, "") | E7: =IF(SubclassAspects!C18>0,"Endurance ", "") -> Endurance | F7: =IF(SubclassAspects!C18>0,SubclassAspects!C18, "") -> 53
C8: =IF(SubclassAspects!C15>0,"Strength ","") -> Strength | D8: =IF(SubclassAspects!C15>0,SubclassAspects!C15, "") -> 54 | E8: =IF(SubclassAspects!C19>0,"Luck ", "") | F8: =IF(SubclassAspects!C19>0,SubclassAspects!C19, "")
C9: =IF(SubclassAspects!C16>0,"Wisdom ","") -> Wisdom | D9: =IF(SubclassAspects!C16>0,SubclassAspects!C16, "") -> 61 | E9: =IF(SubclassAspects!C20>0,"Will ", "") -> Will | F9: =IF(SubclassAspects!C20>0,SubclassAspects!C20, "") -> 54
A11: Overview
A13: Quote: | B13: “With proper preparations, the fighting is merely a formality.”
A14: The Scout is an archer-based class that can act early and effectively. He uses preliminary actions to take control of the battlefield, attacks enemies at full health, and quickens himself readily. He is hard to destroy before his turn.
A15: World Notes: Scouts are an essential part of enemy army, as only with knowledge of the enemy can success be found. The scouts prepare the battlefield to best support their army’s success.
A16: Appearance: The scout is lightly armored because he is constantly on the move.
A17: Defining Mechanic: The Scout can implement scouted abilities. These abilities, which come in all three strengths, can only be used as the first action of battle, after which they turn into a related, but lesser, ability.
A19: Equipment
A20: Default Weapon: | C20: Short Bow
A21: Default Armor:
A41: Major Abilities
A42: Adroit Momentum – Ranged attack with pinpoint and momentum enhancing accuracy (Scout)
A43: Aimed Momentum – Ranged attack that generates extra aim based on momentum (Scout)
A44: Coordinated Shot – Ranged attack with quick preparation that grants increased accuracy and damage to next attack versus target (Scout)
A45: Delaying Jolt – Ranged attack with delay against stunned target (Scout)
A46: Flanking Shot – Ranged attack that causes flanked (Scout)
A47: Lay of the Land – Ranged attack that enhances dodge of team based on aim (Scout)
A48: Quickening Aim – Ranged attack against single target that consumes aim to quicken self (Scout)
A49: Rapid Vow – Prepared ranged attack that determines target on preparation. Quickens scout on preparation and on use (Scout)
A50: Scouted Arrow Burst – Ranged attack against all enemies. Deals less damage and requires aim if not first turn (Scout)
A51: Scouted Chink – Full penetration ranged attack if first attack of battle. Can proc full penetration with ranged attack after (Scout)
... A71: Share Momentum – Quicken all allies based on momentum (Scout)

Sheet SubclassAspects
D1: Hunter | P1: Wrestler | AO1: Siege Engineer | AV1: Rager | CD1: Sword Magus | EQ1: Winter Witch | ES1: Witch Doctor
A2: Name | B2: =COUNTA(C2:FF2)/1.6 -> 100 | C2: Scout | D2: Huntsman | E2: Crossbowman | F2: Marksman | G2: Falconer | H2: Bounty Hunter | I2: Stalker | J2: Poacher | K2: Sharpshooter | L2: Toxophilite | M2: Initiate | N2: Pugilist | O2: Skirmisher | P2: Vajra | Q2: Stonefist | R2: Infiltrator | S2: Viper Fang | T2: Ascetic | U2: Thunderfist | V2: Drunken Master | W2: Bandit | X2: Cutthroat | Y2: Burglar | Z2: Thief | AA2: Acrobat | AB2: Assassin | AC2: Brigand | AD2: Smuggler | AE2: Skulk | AF2: Ninja | AG2: Scavenger | AH2: Alchemist | AI2: Artificer | AJ2: Tinker | AK2: Engineer | AL2: Bomber | AM2: Gunslinger | AN2: Savant | AO2: Machinist | AP2: Reliquarian | AQ2: Brute | AR2: Raider | AS2: Berserker | AT2: Marauder | AU2: Viking | AV2: Vandal | AW2: Fury | AX2: Cannibal | AY2: Destroyer | AZ2: Beastlord | BA2: Gladiator | BB2: Duelist | BC2: Phalanx | BD2: Dervish | BE2: Fencer | BF2: Lancer | BG2: Samurai | BH2: Dreadnaught | BI2: Swashbuckler | BJ2: Warlord | BK2: Bodyguard | BL2: Champion | BM2: Hospitaler | BN2: Cavalier | BO2: Sentinel | BP2: Dragoon | BQ2: Paragon | BR2: Black Knight | BS2: Crusader | BT2: Templar | BU2: Blitzknecht | BV2: Feuerknecht | BW2: Drecknecht | BX2: Trinknecht | BY2: Mercenary | BZ2: Transmuter | CA2: Force Weaver | CB2: Myrmidon | CC2: Nightblade | CD2: Sword Saint | CE2: Minstrel | CF2: Jester | CG2: Dirge Singer | CH2: Balladeer | CI2: Drummer | CJ2: Spy | CK2: Mountebank | CL2: Diva | CM2: Muse | CN2: Lantern Bearer | CO2: Conjurer | CP2: Occultist | CQ2: Shaman | CR2: Medium | CS2: Animist | CT2: Spiritualist | CU2: Astrologer | CV2: Vizier | CW2: Alienist | CX2: Pact Master | CY2: Acolyte | CZ2: Healer | DA2: Disciple | DB2: Priest | DC2: Combat Medic | DD2: Exorcist | DE2: Preacher | DF2: Zealot | DG2: Plague Doctor | DH2: Oracle | DI2: Buccaneer | DJ2: Executioner | DK2: Gravedigger | DL2: Hangman | DM2: Harbinger | DN2: Sin Eater | DO2: Sandman | DP2: Whisperer | DQ2: Mercy Bringer | DR2: Gaslighter | DS2: Telepath | DT2: Kinetic | DU2: Amnesiac | DV2: Hypnotist | DW2: Diviner | DX2: Haunted | DY2: Mastermind | DZ2: Mindbleeder | EA2: Chronomancer | EB2: Puppet Master | EC2: Abjurer | ED2: Symbolist | EE2: Cabalist | EF2: Hermit | EG2: Disenchanter | EH2: Scrivener | EI2: Sage | EJ2: Glyphic | EK2: Cryptic | EL2: Sorcerer | EM2: Cultist | EN2: Warlock | EO2: Effigist | EP2: Dustbringer | EQ2: Crone | ER2: Hedgemage | ES2: Mambo | ET2: Bokor | EU2: Hag | EV2: Malefax | EW2: Elementalist | EX2: Necromancer | EY2: Hydromancer | EZ2: Geomancer | FA2: Aeromancer | FB2: Pyromancer | FC2: Arcanist | FD2: Solomancer | FE2: Incanter | FF2: Thaumaturge
A3: Code | B3: =COUNTA(C3:FF3)/1.6 -> 100 | C3: 2 | D3: 3 | E3: 4 | F3: 5 | G3: 6 | H3: 7 | I3: 8 | J3: 9 | K3: 10 | L3: 11 | M3: 13 | N3: 14 | O3: 15 | P3: 16 | Q3: 17 | R3: 18 | S3: 19 | T3: 20 | U3: 21 | V3: 22 | W3: 24 | X3: 25 | Y3: 26 | Z3: 27 | AA3: 28 | AB3: 29 | AC3: 30 | AD3: 31 | AE3: 32 | AF3: 33 | AG3: 35 | AH3: 36 | AI3: 37 | AJ3: 38 | AK3: 39 | AL3: 40 | AM3: 41 | AN3: 42 | AO3: 43 | AP3: 44 | AQ3: 46 | AR3: 47 | AS3: 48 | AT3: 49 | AU3: 50 | AV3: 51 | AW3: 52 | AX3: 53 | AY3: 54 | AZ3: 55 | BA3: 57 | BB3: 58 | BC3: 59 | BD3: 60 | BE3: 61 | BF3: 62 | BG3: 63 | BH3: 64 | BI3: 65 | BJ3: 66 | BK3: 68 | BL3: 69 | BM3: 70 | BN3: 71 | BO3: 72 | BP3: 73 | BQ3: 74 | BR3: 75 | BS3: 76 | BT3: 77 | BU3: 79 | BV3: 80 | BW3: 81 | BX3: 82 | BY3: 83 | BZ3: 84 | CA3: 85 | CB3: 86 | CC3: 87 | CD3: 88 | CE3: 90 | CF3: 91 | CG3: 92 | CH3: 93 | CI3: 94 | CJ3: 95 | CK3: 96 | CL3: 97 | CM3: 98 | CN3: 99 | CO3: 101 | CP3: 102 | CQ3: 103 | CR3: 104 | CS3: 105 | CT3: 106 | CU3: 107 | CV3: 108 | CW3: 109 | CX3: 110 | CY3: 112 | CZ3: 113 | DA3: 114 | DB3: 115 | DC3: 116 | DD3: 117 | DE3: 118 | DF3: 119 | DG3: 120 | DH3: 121 | DI3: 123 | DJ3: 124 | DK3: 125 | DL3: 126 | DM3: 127 | DN3: 128 | DO3: 129 | DP3: 130 | DQ3: 131 | DR3: 132 | DS3: 134 | DT3: 135 | DU3: 136 | DV3: 137 | DW3: 138 | DX3: 139 | DY3: 140 | DZ3: 141 | EA3: 142 | EB3: 143 | EC3: 145 | ED3: 146 | EE3: 147 | EF3: 148 | EG3: 149 | EH3: 150 | EI3: 151 | EJ3: 152 | EK3: 153 | EL3: 154 | EM3: 156 | EN3: 157 | EO3: 158 | EP3: 159 | EQ3: 160 | ER3: 161 | ES3: 162 | ET3: 163 | EU3: 164 | EV3: 165 | EW3: 167 | EX3: 168 | EY3: 169 | EZ3: 170 | FA3: 171 | FB3: 172 | FC3: 173 | FD3: 174 | FE3: 175 | FF3: 176
A4: Tier | B4: =COUNTA(C4:FF4)/1.6 -> 100 | C4: 1 | D4: 2 | E4: 6 | F4: 7 | G4: 9 | H4: 13 | I4: 15 | J4: 19 | K4: 21 | L4: 25 | M4: 1 | N4: 2 | O4: 6 | P4: 7 | Q4: 9 | R4: 13 | S4: 15 | T4: 19 | U4: 21 | V4: 25 | W4: 1 | X4: 2 | Y4: 6 | Z4: 7 | AA4: 9 | AB4: 13 | AC4: 15 | AD4: 19 | AE4: 21 | AF4: 25 | AG4: 1 | AH4: 2 | AI4: 6 | AJ4: 7 | AK4: 9 | AL4: 13 | AM4: 15 | AN4: 19 | AO4: 21 | AP4: 25 | AQ4: 1 | AR4: 2 | AS4: 6 | AT4: 7 | AU4: 9 | AV4: 13 | AW4: 15 | AX4: 19 | AY4: 21 | AZ4: 25 | BA4: 1 | BB4: 2 | BC4: 6 | BD4: 7 | BE4: 9 | BF4: 13 | BG4: 15 | BH4: 19 | BI4: 21 | BJ4: 25 | BK4: 1 | BL4: 2 | BM4: 6 | BN4: 7 | BO4: 9 | BP4: 13 | BQ4: 15 | BR4: 19 | BS4: 21 | BT4: 25 | BU4: 1 | BV4: 2 | BW4: 6 | BX4: 7 | BY4: 9 | BZ4: 13 | CA4: 15 | CB4: 19 | CC4: 21 | CD4: 25 | CE4: 1 | CF4: 2 | CG4: 6 | CH4: 7 | CI4: 9 | CJ4: 13 | CK4: 15 | CL4: 19 | CM4: 21 | CN4: 25 | CO4: 1 | CP4: 2 | CQ4: 6 | CR4: 7 | CS4: 9 | CT4: 13 | CU4: 15 | CV4: 19 | CW4: 21 | CX4: 25 | CY4: 1 | CZ4: 2 | DA4: 6 | DB4: 7 | DC4: 9 | DD4: 13 | DE4: 15 | DF4: 19 | DG4: 21 | DH4: 25 | DI4: 1 | DJ4: 2 | DK4: 6 | DL4: 7 | DM4: 9 | DN4: 13 | DO4: 15 | DP4: 19 | DQ4: 21 | DR4: 25 | DS4: 1 | DT4: 2 | DU4: 6 | DV4: 7 | DW4: 9 | DX4: 13 | DY4: 15 | DZ4: 19 | EA4: 21 | EB4: 25 | EC4: 1 | ED4: 2 | EE4: 6 | EF4: 7 | EG4: 9 | EH4: 13 | EI4: 15 | EJ4: 19 | EK4: 21 | EL4: 25 | EM4: 1 | EN4: 2 | EO4: 6 | EP4: 7 | EQ4: 9 | ER4: 13 | ES4: 15 | ET4: 19 | EU4: 21 | EV4: 25 | EW4: 1 | EX4: 2 | EY4: 6 | EZ4: 7 | FA4: 9 | FB4: 13 | FC4: 15 | FD4: 19 | FE4: 21 | FF4: 25
A5: Base Class | B5: =COUNTA(C5:FF5)/1.6 -> 100 | C5: Archer | D5: Archer | E5: Archer | F5: Archer | G5: Archer | H5: Archer | I5: Archer | J5: Archer | K5: Archer | L5: Archer | M5: Monk | N5: Monk | O5: Monk | P5: Monk | Q5: Monk | R5: Monk | S5: Monk | T5: Monk | U5: Monk | V5: Monk | W5: Rogue | X5: Rogue | Y5: Rogue | Z5: Rogue | AA5: Rogue | AB5: Rogue | AC5: Rogue | AD5: Rogue | AE5: Rogue | AF5: Rogue | AG5: Teknixian | AH5: Teknixian | AI5: Teknixian | AJ5: Teknixian | AK5: Teknixian | AL5: Teknixian | AM5: Teknixian | AN5: Teknixian | AO5: Teknixian | AP5: Teknixian | AQ5: Barbarian | AR5: Barbarian | AS5: Barbarian | AT5: Barbarian | AU5: Barbarian | AV5: Barbarian | AW5: Barbarian | AX5: Barbarian | AY5: Barbarian | AZ5: Barbarian | BA5: Fighter | BB5: Fighter | BC5: Fighter | BD5: Fighter | BE5: Fighter | BF5: Fighter | BG5: Fighter | BH5: Fighter | BI5: Fighter | BJ5: Fighter | BK5: Knight | BL5: Knight | BM5: Knight | BN5: Knight | BO5: Knight | BP5: Knight | BQ5: Knight | BR5: Knight | BS5: Knight | BT5: Knight | BU5: Spellsword | BV5: Spellsword | BW5: Spellsword | BX5: Spellsword | BY5: Spellsword | BZ5: Spellsword | CA5: Spellsword | CB5: Spellsword | CC5: Spellsword | CD5: Spellsword | CE5: Bard | CF5: Bard | CG5: Bard | CH5: Bard | CI5: Bard | CJ5: Bard | CK5: Bard | CL5: Bard | CM5: Bard | CN5: Bard | CO5: Binder | CP5: Binder | CQ5: Binder | CR5: Binder | CS5: Binder | CT5: Binder | CU5: Binder | CV5: Binder | CW5: Binder | CX5: Binder | CY5: Cleric | CZ5: Cleric | DA5: Cleric | DB5: Cleric | DC5: Cleric | DD5: Cleric | DE5: Cleric | DF5: Cleric | DG5: Cleric | DH5: Cleric | DI5: Reaper | DJ5: Reaper | DK5: Reaper | DL5: Reaper | DM5: Reaper | DN5: Reaper | DO5: Reaper | DP5: Reaper | DQ5: Reaper | DR5: Reaper | DS5: Psychic | DT5: Psychic | DU5: Psychic | DV5: Psychic | DW5: Psychic | DX5: Psychic | DY5: Psychic | DZ5: Psychic | EA5: Psychic | EB5: Psychic | EC5: Runemage | ED5: Runemage | EE5: Runemage | EF5: Runemage | EG5: Runemage | EH5: Runemage | EI5: Runemage | EJ5: Runemage | EK5: Runemage | EL5: Runemage | EM5: Witch | EN5: Witch | EO5: Witch | EP5: Witch | EQ5: Witch | ER5: Witch | ES5: Witch | ET5: Witch | EU5: Witch | EV5: Witch | EW5: Wizard | EX5: Wizard | EY5: Wizard | EZ5: Wizard | FA5: Wizard | FB5: Wizard | FC5: Wizard | FD5: Wizard | FE5: Wizard | FF5: Wizard
A6: Gender | B6: =COUNTA(C6:FF6)/1.6 -> 100 | C6: Male | D6: Male | E6: Male | F6: Male | G6: Male | H6: Male | I6: Male | J6: Male | K6: Male | L6: Male | M6: Male | N6: Male | O6: Male | P6: Male | Q6: Male | R6: Male | S6: Male | T6: Male | U6: Male | V6: Male | W6: Male | X6: Male | Y6: Male | Z6: Male | AA6: Male | AB6: Male | AC6: Male | AD6: Male | AE6: Male | AF6: Male | AG6: Female | AH6: Female | AI6: Female | AJ6: Female | AK6: Female | AL6: Female | AM6: Female | AN6: Female | AO6: Female | AP6: Female | AQ6: Female | AR6: Female | AS6: Female | AT6: Female | AU6: Female | AV6: Female | AW6: Female | AX6: Female | AY6: Female | AZ6: Female | BA6: Female | BB6: Female | BC6: Female | BD6: Female | BE6: Female | BF6: Female | BG6: Female | BH6: Female | BI6: Female | BJ6: Female | BK6: Male | BL6: Male | BM6: Male | BN6: Male | BO6: Male | BP6: Male | BQ6: Male | BR6: Male | BS6: Male | BT6: Male | BU6: Female | BV6: Female | BW6: Female | BX6: Female | BY6: Female | BZ6: Female | CA6: Female | CB6: Female | CC6: Female | CD6: Female | CE6: Male | CF6: Male | CG6: Male | CH6: Male | CI6: Male | CJ6: Male | CK6: Male | CL6: Male | CM6: Male | CN6: Male | CO6: Female | CP6: Female | CQ6: Female | CR6: Female | CS6: Female | CT6: Female | CU6: Female | CV6: Female | CW6: Female | CX6: Female | CY6: Male | CZ6: Male | DA6: Male | DB6: Male | DC6: Male | DD6: Male | DE6: Male | DF6: Male | DG6: Male | DH6: Male | DI6: Male | DJ6: Male | DK6: Male | DL6: Male | DM6: Male | DN6: Male | DO6: Male | DP6: Male | DQ6: Male | DR6: Male | DS6: Female | DT6: Female | DU6: Female | DV6: Female | DW6: Female | DX6: Female | DY6: Female | DZ6: Female | EA6: Female | EB6: Female | EC6: Male | ED6: Male | EE6: Male | EF6: Male | EG6: Male | EH6: Male | EI6: Male | EJ6: Male | EK6: Male | EL6: Male | EM6: Female | EN6: Female | EO6: Female | EP6: Female | EQ6: Female | ER6: Female | ES6: Female | ET6: Female | EU6: Female | EV6: Female | EW6: Female | EX6: Female | EY6: Female | EZ6: Female | FA6: Female | FB6: Female | FC6: Female | FD6: Female | FE6: Female | FF6: Female
A7: Associated Demon | B7: =COUNTA(C7:FF7)/1.6 -> 25 | C7: Ipos | D7: Leraje | E7: Dantalion | F7: Allocer | G7: Pazazu | H7: Baphomet | I7: Demogorgon | J7: Set | K7: Glasya | L7: Andras | M7: Glasya | N7: Gusion | O7: Pazazu | P7: Andras | Q7: Scarmiglione | R7: Sabnock | S7: Orobas | T7: Levistus | U7: Paimon | V7: Gaap | W7: Ipos | X7: Geryon | Y7: Mammon | Z7: Sabnock | AA7: Bifrons | AB7: Glasya | AC7: Gusion | AD7: Orobas | AE7: Andras | AF7: x | AG7: Belial | AH7: Haagenti | AI7: x | AJ7: Mammon | AK7: Orobas | AL7: Tiamat | AM7: Leraje | AN7: Orcus | AO7: Rubicante | AP7: Eligos
A8: Quote | B8: =COUNTA(C8:FF8)/1.6 -> 0
A9: Description | B9: =COUNTA(C9:FF9)/1.6 -> 75 | C9: An early-action specialist who seizes the opening of battle with scouted abilities that can only be used as the first action of a wave, then transform into a lesser related ability afterward. He builds aim quickly, attacks enemies at full health for bonus damage, and is difficult to eliminate before he gets to act. | D9: A distance fighter who uses momentum to enhance his arrows and can penetrate armor more effectively the further away his target is. He tracks a specific enemy type, gaining bonuses against others of the same kind as his primary aim target and hitting harder the longer he sustains focus. | E9: A heavy crossbow specialist who attacks more slowly than other archers but deals more damage per shot with greater penetration. He is more defensive than most archer subclasses, reacting to enemy attacks against him rather than purely pressing offense, and can fortify and reload quickly between shots. | F9: An accuracy and penetration specialist who places marks on enemies that grant his allies benefits when they attack the same targets. He is the team's force multiplier at range, making his aim target more dangerous for everyone and sharing his exceptional accuracy with those who follow his lead. | G9: A companion-focused archer whose pet falcon harries targets and enables abilities that either work better in the falcon's presence or require it outright. He uses the falcon to set up aim, distract enemies, and coordinate strikes — making his companion an active offensive asset rather than a passive attendant. | H9: A capture-specialist who places bounty afflictions on enemies as minor actions during combat, with those bounties triggering beneficial effects when the marked enemy dies. He can stun and incapacitate targets to take them alive, gaining increasing payoffs the more bounties he has active when enemies fall. | I9: A shadow-fighter who generates aim from hidden status and converts high accuracy into higher damage, with a defining ability that expends all accumulated aim for a devastating single attack — but then prevents him from targeting that specific enemy for a period scaled to the aim spent. | J9: A kill-opportunist who triggers immediate prepared attacks the moment an enemy becomes endangered, without those poach abilities being interruptible by damage. He gains culling abilities, preferences for specific target types, and benefits from kills — a specialist at finishing weakened prey faster than anyone else can reach them. | K9: A trick-shot specialist whose accuracy-dependent abilities pierce through targets to hit columns behind them and have reduced hit chance but significant effects when they connect. His trick shot success rate scales with current aim relative to maximum aim, rewarding sustained focus on a single target before committing to the high-risk high-reward shots. | L9: A distance-and-duration specialist who builds power over the course of a long battle through eternal buff abilities that grow without limit but become progressively more expensive to enhance. Only one can be active at a time, demanding that the player commit to a single compounding effect and protect the Toxophilite long enough for it to pay off. | M9: A patient striker who builds power by holding his form and releases it explosively on transition. His unleash mechanic rewards stillness — the longer he stays in a single form, the more devastating the eventual change. He has no form preference, making him the most flexible of the monk subclasses and a strong foundation for learning the chakra system. | N9: A relentless single-target brawler who punishes the same enemy turn after turn through his impact mechanic. Any enemy he struck last turn becomes the target of a suite of specialized follow-up attacks covering damage, delay, disruption, and control. Lower chakra focused and strength-enhanced, he hits harder the longer he stays locked onto one target. | O9: A fast, opportunistic fighter who mirrors his enemies' own strengths against them through the matching mechanic. He can temporarily adopt a target's critical stats, damage, accuracy, defense, or dodge — turning powerful enemies into their own worst nightmare. Leopard form focused and haste-driven, he excels at demolishing stunned foes and stacking bleeds through repeated Leopard Claw cycles. | P9: An immovable reactive combatant who weaponizes his chakra configuration to punish every enemy attack. Snake's Response reflects conditions back at attackers based on which chakras are open, with the lower chakras delivering the most devastating punishments — prone, delay, and disarm simultaneously at full configuration. He fights best when pristine, baiting attacks while armed with Reversal, Absorbed Counter, and a full suite of prepared reactions. | Q9: A fortified earth specialist who turns glancing blows from a weakness into a weapon. His attacks deliberately seek glancing hits to trigger stuns, bleeds, delays, and fragility — and his Pressure Crack capstone extends this to critical hits as well. Tiger form focused and endurance-heavy, he is nearly immovable under sustained assault and punishes enemies for every attempt to pierce his defenses. | R9: A burst-damage specialist who cycles through hidden states to deliver devastating arrival attacks. Each time he loses hidden — whether by choice or enemy action — he unleashes a different arrival ability covering area damage, flanking, stunning, or penetrating strikes. Mantis focused and initiative-driven, his Exposed Momentum capstone ensures every exposure accelerates his next turn. | S9: A poison-crafting snake form specialist who generates unique toxins from his own body and bleeds. He creates poisons based on his current form through Venom Chakra, conserves and refreshes them through careful resource management, and delivers them through venomous, insidious, and backbiting strikes. Earth and dark elemental focused, he excels at sustained damage over time and attrition warfare. | T9: A disciplined dragon form purist who draws power from maintaining a state of perfect purity. His most powerful abilities — Fist of Purity, Double Purity, Whirlwind Purity — require being completely unafflicted, while his Condition Fortress capstone makes him progressively harder to afflict as conditions accumulate. He manages corruption, stuns enemies with dragon-powered strikes, and uses focus as both a resource and a defensive tool. | U9: A chain-combat specialist who builds devastating sequences of air, stun, and shatter effects through careful ability ordering. Nearly every move and minor ability has a trigger condition — following a counter, a critical, a shatter, or an air attack — creating dense combo potential that rewards mechanical knowledge. Crane focused and counter-driven, his Thunder Strikes capstone ensures every stunned enemy takes bonus air damage on each hit. | V9: A chaotic form-shifting brawler who embraces randomness and prone states as sources of power rather than liability. He shifts forms rapidly to build Fluid Punch damage, reach Ultimate Punch thresholds, and trigger Chakra Ascension — while deliberately falling prone to counter from the ground and punish enemies with Misplaced Retribution. His unpredictability is his greatest defense, with low accuracy offset by high dodge and a tendency to accidentally hit exactly the wrong person at exactly the right time. | W9: A quick ranged harasser who opens battle at a distance before pivoting to a more dangerous close-quarters fighter when his allies fall. He carries desperation abilities that only activate when he stands alone, rewarding survival over coordinated play. | X9: A dualwield melee brawler who stacks bleed on enemies through relentless two-weapon exchanges and can grant himself intangibility to press the offense without interruption. His advantage generation rewards staying in the fight and bleeding targets dry. | Y9: An ambush specialist who hits hardest against undamaged enemies and strips buffs from those who have fought back. He can artificially recreate full-health windows late in battle by corrupting enemy maximum health, keeping his ambush toolkit relevant throughout. | Z9: A self-sufficient dualwield fighter who steals accuracy, speed, and senses from enemies to empower himself. He can briefly share his incoming healing and mana gain with allies, giving a team-oriented edge to an otherwise personal playstyle. | AA9: A dodge-focused rebuild Rogue who invites attacks, turns misses into advantage, and uses reliable abilities that refund their costs on failure. He thrives in the open and under illumination, unlike most Rogues who prefer the shadows. | AB9: A single-target executioner who signs contracts against chosen enemies, gaining combat bonuses while pursuing them and earning powerful fulfillment rewards when he personally lands the killing blow. Five contract types let the player tailor each hunt to the situation. | AC9: A ranged gambler who wagers advantage and mana on battlefield conditions, collecting larger payoffs when those conditions are met. A good run leaves him flush; a bad one leaves him empty, making risk tolerance the central skill of his playstyle. | AD9: A team-oriented Rogue whose power scales with how many allies are hidden alongside him. He can blanket the party in shadow, share his poisons across the team, and coordinate hidden allies into a unified striking force. | AE9: A defensively self-reliant Rogue who applies aversion to make enemies ignore him, then punishes them for it. He complements aversion with scorn to layer targeting protection, generating advantage steadily from the safety of being overlooked. | AF9: A hidden-mastery specialist who chains haste, advantage, and free bonus attacks by maintaining concealment across multiple actions. He rewards players who have mastered the hidden economy, with insidious attacks and precise sequencing separating competent play from exceptional play. | AG9: A chaotic support-attacker who thrives on unpredictability. Her scavenged abilities reveal their element on preparation rather than use, making her toolkit flexible but harder to plan around. She generates ammo from kills and builds belts from whatever she has on hand — a scrappy, resource-efficient subclass that rewards improvisation. | AH9: A prepared-resource specialist who enters battle with concoctions already brewed and ready to use without cost or preparation. She leans into healing, poison, and resurrection, and her premade system lets her open waves with full-power abilities immediately. Her capstone Premade Reserves deepens this advantage, making her the Teknixian most oriented toward sustained party management. | AI9: A trap-setter and accumulator who builds up power before releasing it. Her accumulation abilities charge on first use and discharge on second, rewarding patience with amplified outputs. She also controls the detonation chain — recovering, redirecting, and shielding through it — and provides elemental shields to allies via Teknos Shielding. | AJ9: A modification-based companion commander who toggles different behavioral modes to reshape her companion and her own attacks. Her four modular abilities — Modular Bomb, Modular Ray, Modular Trap, and Modular Beam — each change behavior based on which modifications are active. Flame Spewer and Lightning Tosser are ammo-sensitive companions that change element and effect based on what's loaded at summoning. | AK9: An ally-empowerment specialist who assigns persistent assistant enchantments to party members. Each assistant type triggers a different proc when the assigned ally attacks — shields, heals, traps, bonus attacks, or quickening — and Activate Assistant can fire all procs simultaneously. She also fields the Shield Guardian, a fixed-behavior healing companion with no ammo interaction, and Minefield Assistant turns any attacker into a trap-seeding machine. | AL9: A high-risk area damage dealer whose bomb abilities hit allies and enemies identically with no discount. She layers countdowns on enemies and manages the self-threat they create using Accept Explosion, Accept Mass Explosion, Gift Bomb, and Transfer Countdown. Explosion Imminent and Kinetic Protection let her mitigate her own friendly fire. The higher the aim output, the harder the landing. | AM9: A pure ranged damage dealer built around called shots and burst ammo expenditure. Called shots are prepared as a minor action, name a target, and add powerful debuff effects — disarm, stun, heartstrike, slow, or delay — to the first attack used against that target on the following turn. Full Clip and Oblivion Shot are her all-in damage options. High Noon and Showdown both guarantee a counter-attack against her, rewarding Take Cover setups. | AN9: A slow-burn debuff-accumulator whose six concoctions apply ongoing effects while building power each clock tick, then discharge a scaled effect when the chain fires or time runs out. More ammo at placement extends the window and increases accumulated power at detonation. A Faraday sub-theme lets her wear lightning rod deliberately and redirect incoming storm damage offensively through Faraday Connection's pain link. | AO9: A companion-amplifier who fields extremely slow, powerful siege engine companions — Ballista, Battering Ram, and Catapult — and spends her own actions making them fire more frequently. Every move and minor ability in her kit serves the companion: Operate Siege Engine quickens it directly, Teamwork Operation converts party delay into companion clock advancement, and Siege Command upgrades whatever the companion would do next. Her own attacks like Amplifying Cannonshot and Earth Cannon give her meaningful damage when she steps away from the engine. | AP9: A relic-stacking power escalator who activates multi-ability relics that grow stronger with each ammo devotion. Each devoted ammo type is locked until the relic ends — which it cannot be cancelled until max devotion — creating deep commitment costs in exchange for battlefield-wide buffs, persistent damage, companion power, or trap generation. Relic Blast and Relic Bolt scale with total ammo devoted across all active relics, making a fully stacked Reliquarian increasingly devastating the longer a wave goes on. | AQ9: The patient tank of the Barbarian family. A slower, higher-endurance variant who defers self-damage costs to the next turn through Consequences, generating Anguish immediately while controlling when the pain lands — or redirecting it to enemies entirely with Share Consequence. | AR9: A shield-and-weapon fighter who builds active defenses only to spend them all at once. Reckless abilities consume all block, dodge, and counter values for amplified attacks, rewarding players who time the exposed window around a supporting tank or use it as a finisher when consequences can't resolve. | AS9: The chaos amplifier of the family, built around Exertion abilities that generate Anguish from repeated misses and spread destruction through Contagious Temper. She leans fully into the Berserk condition, turning random targeting from a liability into an engine, with the Panic pair offering a rare moment of choice between embracing or escaping the disorder. | AT9: A dual-wield closer who grows faster and hits harder the more enemies die. Rampage scales with kills — personal kills more than team kills — making bloodlust and counter abilities the tools that keep her offense rolling between turns and feeding the escalation she depends on. | AU9: A deliberate shield fighter who charges prepared abilities through sustained blocking. Each block adds power to any held ability, and multiple prepared abilities charge independently, rewarding patient setup and precise release timing over the Raider's impulsive spending. | AV9: Pure escalating output. She accumulates damage dealt toward a threshold that briefly unlocks Brink abilities — powerful options that vanish if not taken — and can sustain Endless Wrath longer than any other subclass before the drain finally overtakes her. | AW9: Precise and fast, with a discipline that belies her name. Purity abilities amplify with each use but cancel on specific failure conditions, demanding focused play to maintain multiple stacks simultaneously. She grows faster as she takes damage and reaches peak power when Wrath and Berserk combine. | AX9: A self-sustaining predator who stays hurt to stay fed. Her healing threshold mechanic unlocks powerful abilities as applicable healing accumulates, rewarding healers who time large heals over constant top-offs, while life drain and kill-reaction heals give her independence when the support is occupied elsewhere. | AY9: The armor-stripping heavyweight, built to cross the massive damage threshold and trigger cascading effects that tear down enemy defenses for the whole team. Destruction Wrath amplifies weakness power and defense reduction, but ends in forsaken and strips all enchantments — making dedicated buffers a liability rather than an asset. | AZ9: The apex predator and most complex of the Barbarian subclasses. She cycles between four exclusive beast forms, scales overkill into team-wide debuffs, and generates Anguish from damage dealt to any ally — turning chaotic encounters into fuel. Final Wrath guarantees her death when it ends, making every use of it the last decision she makes. | BA9: A flashy, risk-taking fighter who uses gambit abilities that either succeed spectacularly or backfire against her. Critical Stance generates expertise on critical hits, and her gambits deal high damage or critical effects at a cost — such as becoming prone on a miss or inviting counter attacks — rewarding aggressive play with chain weapons. | BB9: A one-handed sword specialist who excels at counter attacks and is almost impossible to disarm or knock down. Counter Stance generates expertise whenever she counters, and her kit is built around parries and ripostes — parrying an attack, then immediately punishing the attacker with a follow-up strike. | BC9: A heavy shield bearer who fights best alongside ready allies. Shield Stance generates expertise on every block, and her toolkit includes guaranteed blocks, fortification at the cost of tired, and Phalanx Power, which enhances the damage of all ready allies based on how many are still standing. | BD9: A dual-wielding speed specialist whose defining abilities trigger on the second strike of a sequence, becoming more powerful the sooner that second hit follows the first. Speed Stance generates expertise from quicken effects, and she builds momentum and haste through attacks to fuel an escalating flurry of blows. | BE9: An extraordinarily accurate fighter who specializes in pinpoint attacks that can activate additional conditions at high enough values. Pinpoint Stance generates expertise from hit rolls beyond what is needed to connect, and her kit rewards fighting alone — with Alone Damage and Alone Defense passives that keep her effective as the last fighter standing. | BF9: A polearm and spear specialist whose Lancing Blow attacks have a chance to pierce through the primary target and hit the enemy behind them. Retaliation Stance generates expertise through retaliating, and she brings mounted abilities and column-targeting attacks that reward controlling space and threatening multiple rows at once. | BG9: An initiative-focused dual-wielder who seizes the opening of every battle with maximum aggression. Dodge Stance generates expertise on dodges, and Suicide Stance trades increased offense and counter-chance for the willingness to be struck, generating expertise from taking hits and rewarding an all-or-nothing fighting style. | BH9: An immovable defensive combatant who weaponizes his durability offensively. Unmovable Stance generates expertise from movement effects targeting him, and Advanced Unmovable Stance reflects delays back at enemies, turning every attempt to slow him into a punishment for the attacker. | BI9: A sword-fighting parry expert whose feint abilities compel enemies to attack her, then punish them when she parries the incoming strike. Parry Stance generates expertise from each successful parry, and she chains feints into ripostes, bleeds, penetrating attacks, or mass taunts depending on which feint variant she has prepared. | BJ9: A commanding leader who translates her own expertise directly into team-wide benefits. Warlord's Stance generates expertise whenever any ally acts, and her Leadership abilities require a minimum expertise level and become more powerful at higher thresholds — quickening all allies, enhancing their damage, or even making their next attack unerring after she misses. | CE9: Crescendo-driven buffer who rewards spending small actions on allies to power up larger payoffs. Builds Crescendo stacks through move and minor buffs, then releases them through scaling heal, shield, damage, bleed, and mana abilities. Leans toward chords and positive effects, with strong regeneration support alongside his offensive Crescendo tools. | CF9: Chaos-specialist who floods enemies with random afflictions, unpredictable conditions, and misdirected attacks. No formal mechanic — the unpredictability is the design. Best used to overwhelm enemy resistances and create openings for allies, with a capstone that turns his own misfortune into tempo. | CG9: The most offensively oriented bard subclass, specializing in life drain, culling, and damage-focused dischords rather than traditional support. He turns the song mechanic toward attrition and erasure — draining life, finishing weakened enemies, and using death itself as an element of his performance. Cacophony abilities reward the whole team's investment in debuffing, making him most dangerous in coordinated groups. | CH9: Earth-focused sustain specialist who stacks litany effects on allies and enemies for escalating pressure. Juggles short-duration stacking conditions that demand constant reapplication — letting them expire collapses the investment. Extended Cuts rewards commitment by progressively raising duration ceilings the more a condition is refreshed. | CI9: Elemental support and disruption specialist who grants deity-named favors to allies, healing them and loading them with elemental damage adds. Simultaneously harasses enemies with water and air magic, knockdowns, and delays. Favor of the Drum doubles every favor with a free untyped add, making his allies' attacks substantially more dangerous. | CJ9: Stealth-integrated bard who supplements song management with disguises and flanking setups. Each disguise grants role-specific bonuses and can be dramatically discharged for a powerful effect at the cost of the disguise itself. Begins every battle already in disguise, giving immediate access to his full toolkit from the first action. | CK9: Dark magic manipulator who fights most effectively when enemies cannot see him. Avert, scorn, and hidden each provide a different path to his veiled abilities, which hit harder than normal. Elusive Rhythm turns successful misdirection into tempo, rewarding a Mountebank who keeps multiple avoidance conditions active simultaneously. | CL9: Conductor-style support who grants allies free attacks through Entourage abilities, drawing enemy aggression onto protected performers. Provokes and taunts redirect incoming damage to allies who are simultaneously shielded, dodging, or enduring. Dedicated Entourage extends every provoke granted, making each protected performer absorb more before attention shifts. | CM9: Resurrection-focused support whose most powerful abilities unlock only after an ally returns to life. Epiphany abilities turn each resurrection into a cascade of heals, buffs, mana, and free attacks. His retaliation theme gives him an offensive identity when not raising allies, and Encore ensures he can survive long enough to finish his performance. | CN9: Aura-and-light specialist who illuminates the battlefield to empower allies and punish enemies. Manages multiple sustained auras simultaneously while spreading illuminate to lock enemies out of hidden and set up targeted light abilities. Constant Light makes him a hard counter to all stealth-based enemy strategies, fundamentally reshaping how battles play out at Tier 25. | CO9: A summoner who fights in concert with her conjured allies, using their mana reserves to amplify her own attacks. She manifests spectral weapons for any ally and directs her companion with precision, growing stronger the more she and her creature act as one. | CP9: A Thanatos-leaning controller who wraps herself and allies in retaliatory spirits, punishing enemies for every strike they land. She pairs water and air magic for freeze and delay with a cross-alignment toolkit that rewards deliberate dips into Eros. | CQ9: A support specialist who prepares a battery of Attendant abilities and waits for her companion to critical — triggering all of them at once in a cascade of healing, damage, and quickening. The longer she waits, the more devastating the payoff. | CR9: A balanced-alignment caster who draws equal power from both dark and light, strongest when she resists pushing to either extreme. Her Harmony abilities detonate from center for massive effect, then push her off balance — and she spends the next turns clawing her way back. | CS9: A spiritual warrior who infuses her companion with procs before it acts and rides a summoned Spirit Beast into mounted combat. She synchronizes her actions with her creature through a shared spiritual bond, raising fallen companions and granting her allies the will to survive past death. | CT9: A desperation specialist whose entire toolkit unlocks at low health, becoming most powerful precisely when she should be most vulnerable. Her transformation locks in that endangered power permanently, turning near-death into a lasting combat state. | CU9: A critical-hit amplifier who builds toward celestial thresholds across multiple turns, generating mana, quickening herself, and purging afflictions with each enemy she crits. She wields the full elemental spectrum through a stellar lens, with her lucky damage toolkit turning probability itself into a weapon. | CV9: A selfish corruptor who damages her own allies to fuel her offensive power, scaling with the total corruption she spreads across the battlefield. She transforms her own self-inflicted corruption into a permanent power state, and turns enemy deaths into mana through Dark Harvest. | CW9: A sanity-sacrificing chaos mage who deliberately accumulates illusory damage on herself to unlock her most powerful abilities. She cannot be killed by her own madness — but when it expires, it becomes very real, making resource management a matter of survival. | CX9: A high-commitment alignment specialist who signs powerful ongoing Pacts, each granting two bonuses at the cost of one persistent drawback. She thrives at the extremes of the alignment scale, and her Lifebond with her companion means their fates are literally intertwined — she cannot fall while it stands. | CY9: Quick and affordable support built around lucky manipulation and regeneration. Generates divinity through hexes, purges, and blessings, then spends it on Benedictions — powerful single-target heals enhanced by current divinity, with overheal effects that range from possession to damage to speed depending on the type used. | CZ9: Pure restoration specialist with the mana economy to sustain heavy healing across a long battle. His cures carry addenda that scale with heal value, turning strong heals into purges, quickens, or damage adds. A Life Domain running on overheal generation lets him convert aggressive healing directly into sustained divinity. | DA9: Affliction-resistant purge specialist who turns enemy pressure into elemental retaliation. Elemental purges double as generators and resistance enhancers scaled to current divinity, and a Protection Domain that rewards affliction resistance creates a feedback loop where enemy affliction pressure fuels his own power. | DB9: Magically aggressive Cleric who layers blessings onto allies while maintaining his own damage shield as an offensive weapon. The Lattice ability line scales with and consumes his shield for light damage and control, Lattice Reflection punishes enemies who target it, and a Sun Domain that generates from light abilities rewards sustained Celestial offense. | DC9: Frontline healer built for endangered allies and active combat. Vitality heals grant temporary bonuses that persist until the target takes damage, and a War Domain that generates from any ally's critical hits rewards pairing him with damage-heavy parties. Perilous Divinity marks low-health targets for stronger healing while generating divinity. | DD9: Light-magic specialist with exclusive access to intangible enemies and strong mana drain. Most abilities gain additional effects against incorporeal targets, and an Exorcism Domain that generates divinity proportional to total enemy mana spent rewards fighting caster-heavy encounters where the domain becomes a powerful self-sustaining engine. | DE9: Sleep-focused controller who worships the sleeping god and grows in power while the world slumbers. Incapacitated allies feed Rest Domain divinity generation even without the Preacher acting, turning sleep from a liability into a resource. Turns ally afflictions into advantages and punishes sleeping enemies with a focused suite of nightmare attacks. | DF9: High-speed melee Cleric who conducts the entire party's tempo through quickening. Ascension abilities require but do not spend full divinity, creating a maintain-and-hold pattern rather than the typical spend-and-rebuild cycle. A mastery class at Tier 19 — maximizing output requires deep awareness of quicken tolerance, Ascension timing, and Fervor Domain generation simultaneously. | DG9: Self-infecting contagion spreader who carries disease deliberately to fuel his domain. Plague Domain generates divinity for each affliction successfully transferred from the Plague Doctor to an enemy, rewarding stacking afflictions on himself and building around affliction resistance to survive the risk. One of the most dangerous and mechanically demanding Cleric subclasses. | DH9: Capstone Cleric whose Furtherance abilities scale with divinity gained during the current turn rather than total on hand. Front-loading a turn with support actions directly amplifies his payoff. A Prophecy Domain that generates divinity when countdowns fire — scaled to their duration — rewards patience and long-term planning over reactive play. | DS9: The entry point for deep influence play. The Telepath specializes in illusory damage and disruption, with heightened abilities that let her translate influence investment into cascading multi-cast effects. She is subtle and methodical, chipping away at enemy defenses before they can act. | DT9: A spread-oriented damage dealer who turns punishment into power. Her kinetic abilities charge between turns based on physical damage she absorbs, making her uniquely dangerous when enemies focus on her. She favors broad pressure and area control over single-target dominance. | DU9: A denial specialist who erodes the enemy's ability to function. She burns through mana, forces enemies into basic attacks, and makes them forget what they were doing. She also carries an unexpected compassionate edge, helping allies forget their wounds. | DV9: A pattern-weaver who controls the entire battlefield through sustained channeled effects. She locks enemies into states of blindness, stun, or vulnerability for as long as she can keep her focus. Patient and methodical, she rewards players who plan their turns carefully. | DW9: An information broker and countdown specialist who fights the future rather than the present. Her divinations expose enemy weaknesses and upcoming actions, letting the whole party respond intelligently, while her countdown abilities punish enemies for the passage of time itself. | DX9: A ghost-touched subclass who exploits enemies at their weakest — specifically when their mana runs dry. She drains, haunts, and possesses with impunity against vulnerable targets, and can become intangible herself to frighten and evade. Death Knell makes her the safest handler of deep influence. | DY9: The party coordinator. Rather than dominating enemies directly, she possesses allies to direct them more efficiently and uses total influence to synchronize team timing. She rewards players who understand their whole roster and rewards smart sequencing over raw power. | DZ9: A high-risk, high-reward glass cannon who bleeds the mind as much as the body. She deals devastating illusory damage that grows stronger the closer she is to death. Her own abilities hurt her, but the connection flows both ways — and she intends to make that cost worth it. | EA9: A spread-influence subclass who bends time itself to delay, rush, and disorient the battlefield. She punishes fast enemies, accelerates allies, and becomes more efficient the more she leans into her hasted or slowed states. Supreme Chronomancy is one of the most powerful single abilities in the psychic tree. | EB9: The pinnacle of possession mastery. She owns enemies outright, bends their will across multiple turns, and profits from every attack they make under her control. Her capstone, Broken Will, ensures that no enemy is ultimately beyond her reach. | EM9: A team-oriented controller who drains stats from maledicted enemies and redistributes them to allies. She weaponizes possession and hexes for direct control while her Malign drain suite debilitates entire maledicted groups — and Share in Consumption ensures no drain benefit passes through her hands without leaving something behind. | EN9: An air-element Witch who turns malediction into a positional weapon. Her whirlwind abilities use a maledicted enemy as an anchor, striking all adjacent foes instead — rewarding grid awareness and central positioning. Bloodlust amplifies her storm attacks while Conductivity makes the entire maledicted field a lightning rod. | EO9: The most aggressive Witch subclass, stacking damage afflictions on targets to fuel piercing effigy attacks that cut through resistance. Flammability turns every fire hit into compounding bleeds, and Personal Effigy rewards taking damage herself — making her a high-risk attacker who burns hotter the more punishment she absorbs. | EP9: A methodical earth-element controller who applies permanent unending afflictions that reserve her mana until enemies die or are purged. She trades mana flexibility for devastating long-term debilitation, and Mana From Dust recycles her investment when corruption finishes the job. | EQ9: A water-element specialist who deals increased damage and effects in inverse proportion to enemy speed — making her strongest against the foes she has already slowed. Chill to Frost converts redundant slows into hard incapacitation, and Inspiring Misfortune makes her one of the strongest mana generators in the entire Witch family. | ER9: A chaotic generalist who trades reliability for volume, deploying cheap bewitch afflictions against maledicted enemies at reduced action cost. Agnostic Afflictions removes elemental opposition penalties on vulnerability and exposure, letting her stack conditions freely regardless of enemy resistances — chaos as a feature, not a flaw. | ES9: A light-element support Witch who harvests fetishes from fallen enemies and deploys them as stat-scaling ally buffs. She transfers afflictions from allies to enemies, drains life, and accumulates mana through Fetish Bag by holding fetishes in reserve — balancing the tension between deploying her toolkit and sustaining herself. | ET9: A dark necromancer who builds zombie companions from killed and afflicted enemies, using Juju Curse to turn her entire malediction toolkit into a zombie pipeline. Corpse Pile makes each death — enemy or companion — strengthen her current zombie, turning attrition into escalating companion power. | EU9: A corruption and bleed specialist who wraps her worst afflictions in criterion shells that resist purging until they deal their full damage. Expiration Surge turns every naturally expiring condition into mana, rewarding patience and long-duration stacking — Plague Cauldron's exponential corruption release is her most catastrophic payoff for waiting. | EV9: The apex Witch, combining covenants, curses, and mass malediction into a comprehensive affliction dominance platform. She channels malediction across entire enemy groups with Malefaction Chant, unifies damage through Sympathy, and elevates her whole party's affliction pressure through Cursed Amplification — the Witch's toolkit at its most absolute. | EW9: All-elements generalist with companion support and momentum-driven efficiency. She cycles through every element in sequence to build stacking cast speed and mana bonuses, summons earth and water elementals, and infuses allies with elemental damage adds — the most versatile and accessible wizard subclass. | EX9: Dark magic specialist who turns death itself into a resource. She raises skeletal companions, scales her storm damage to the body count, and runs a suite of prepared abilities that trigger automatically when enemies fall — rewarding her for battles where allies are doing the killing as much as her own. | EY9: Control-focused water specialist with the deepest incapacitation toolkit in the class. She freezes, slows, and delays entire battlefields, with her most powerful conflux ability scaling both the number of targets incapacitated and how hard they are to wake based on how many elements she has charged. | EZ9: Defensive earth specialist who protects allies while grinding down enemy defenses. She builds damage shields, roots enemies in place, and applies layered weaknesses — her conflux abilities uniquely favor the whole party by granting elemental retaliations and stacking debuffs across every stat. | FA9: High-variance air specialist built around storm damage and stun pressure. She thrives on randomness — chaining lightning across the grid, forking attacks into splits, and stacking storm hits to overwhelm enemies — with the highest individual damage ceiling in the class when lucky damage and maximum damage align. | FB9: Area fire specialist who hits everyone, repeatedly. She applies countdowns, causes wounds, and commits fully to upfront mana costs for abilities that pay off over multiple ticks — Catastrophe and Conflux Meteor reward planning several turns ahead and punish enemies who cannot interrupt her. | FC9: Anti-attunement specialist who grows stronger the more completely she clears her elemental slate. She is the only wizard whose peak performance comes after spending conflux rather than before it, with her most powerful abilities gating behind having no attunements and her conflux damage rewarding precise elemental power investment over breadth. | FD9: Light magic specialist with hex, justice, and a unique mana economy identity. She wants enemies casting expensive spells so her Mana Disparity bonus peaks, making her the only wizard who benefits from enemy casters. Her full-conflux Conflux Enchantment can grant the entire party six simultaneous buffs scaled to her elemental investment. | FE9: Reactive counterspell specialist who punishes enemy spellcasting while sustaining channeled damage. She runs a suite of prepared counterspells that can chain indefinitely, drains mana from enemies, and uses Conflux Channeling to chain successive elemental damage sequences — the only wizard subclass that gets stronger the more the enemy commits to magic. | FF9: Pinnacle attunement-breadth specialist who rewards deliberate, expensive play. She wants all six elements charged simultaneously, spends them through Supreme abilities that scale with attunement count, and uses her previous turn's mana expenditure to amplify the next — the most technically demanding wizard subclass and the one with the highest ceiling.
A10: Mechanic | B10: =COUNTA(C10:FF10)/1.6 -> 0
A11: Lore | B11: =COUNTA(C11:FF11)/1.6 -> 0
A12: Appearance | B12: =COUNTA(C12:FF12)/1.6 -> 0
A13: Req Dex | B13: =COUNTA(C13:FF13)/1.6 -> 12.5 | C13: 58 | D13: 63 | E13: 62 | F13: 88 | G13: 70 | H13: 142 | I13: 180 | J13: 248 | K13: 193 | L13: 182 | M13: 59 | N13: 58 | O13: 93 | P13: 76 | Q13: 67 | R13: 173 | S13: 88 | T13: 185 | U13: 217 | V13: 263
A14: Req Int | B14: =COUNTA(C14:FF14)/1.6 -> 3.75 | K14: 90 | L14: 108 | M14: 56 | N14: 54 | R14: 77 | S14: 129
A15: Req Str | B15: =COUNTA(C15:FF15)/1.6 -> 8.125 | C15: 54 | E15: 75 | F15: 76 | I15: 86 | L15: 121 | M15: 54 | N15: 64 | O15: 72 | P15: 92 | Q15: 105 | S15: 95 | U15: 140 | V15: 129
A16: Req Wis | B16: =COUNTA(C16:FF16)/1.6 -> 6.25 | C16: 61 | D16: 63 | E16: 72 | G16: 108 | H16: 95 | I16: 80 | J16: 98 | K16: 95 | T16: 90 | V16: 118
A17: Req Cha | B17: =COUNTA(C17:FF17)/1.6 -> 9.375 | C17: 58 | D17: 67 | E17: 84 | F17: 86 | G17: 130 | H17: 95 | I17: 82 | J17: 99 | K17: 238 | L17: 244 | P17: 63 | Q17: 68 | R17: 109 | U17: 131 | V17: 118
A18: Req End | B18: =COUNTA(C18:FF18)/1.6 -> 7.5 | C18: 53 | E18: 63 | M18: 59 | N18: 67 | O18: 82 | P18: 106 | Q18: 85 | R18: 82 | S18: 213 | T18: 185 | U18: 135 | V18: 128
A19: Req Luc | B19: =COUNTA(C19:FF19)/1.6 -> 6.25 | D19: 59 | E19: 62 | F19: 87 | H19: 95 | I19: 82 | J19: 198 | K19: 96 | L19: 245 | O19: 61 | V19: 122
A20: Req Wil | B20: =COUNTA(C20:FF20)/1.6 -> 8.125 | C20: 54 | G20: 70 | H20: 95 | I20: 115 | K20: 96 | M20: 60 | N20: 59 | O20: 60 | Q20: 103 | R20: 81 | T20: 183 | U20: 135 | V20: 122
A21: Weapon Name | B21: =COUNTA(C21:FF21)/1.6 -> 100 | C21: Short Bow | D21: Reflex Bow | E21: Heavy Crossbow | F21: True Shot | G21: Recurve Bow | H21: Bolas | I21: Flatbow | J21: Springbow | K21: Composite Bow | L21: Mach Bow | M21: Katar | N21: Brass Knuckes | O21: Tekko | P21: Spiked Knuckles | Q21: Boulder Gauntlet | R21: Neko-te | S21: Bagh Nakh | T21: Bo Staff | U21: Stormgloves | V21: Steins | W21: Blowgun | X21: Shiv | Y21: Crowbar | Z21: Switchblades | AA21: Trapeze Wire | AB21: Stiletto | AC21: Loaded Dice | AD21: Contraband | AE21: Alleyknives | AF21: Paired Jittes | AG21: Ethermist | AH21: Needlegun | AI21: Force Rifle | AJ21: Chaos Cannon | AK21: Stone Blaster | AL21: Scattershot | AM21: Sacred Revolvers | AN21: Water Pistol | AO21: Hand Catapult | AP21: Phantasm Generator | AQ21: Greatclub | AR21: Battle Axe and Spiked Shield | AS21: Lochaber | AT21: Double Axe | AU21: Francisca and Half Shield | AV21: Ravager | AW21: Dual Axes | AX21: Headsplitter | AY21: Battle Scythe | AZ21: Labrys | BA21: Trident and Net | BB21: Rapier | BC21: Pilum and Scutum | BD21: Double Flail | BE21: Estoc and Bracer | BF21: Longspear | BG21: Katana and Wazikashi | BH21: Maul | BI21: Foil and Parry Dagger | BJ21: Halberd and Shield | BK21: Flanged Mace and Hard Shield | BL21: Broadsword and Wideshield | BM21: Gurz | BN21: Lance and Shield | BO21: Bec de Corbin and Bastion Shield | BP21: Great Lance | BQ21: Paired Batons | BR21: Spiked Ball and Chain | BS21: Morgernstern | BT21: Lucerne and Temple Shield | BU21: Stormbreaker | BV21: Flamberge | BW21: Frostbrand and Waveshield | BX21: Bearded Axe and Timber Shield | BY21: Sellswords | BZ21: Catalyst | CA21: Phasehammer | CB21: Mordaxt | CC21: Voidblades | CD21: Zweihander | CE21: Flute | CF21: Trumpet | CG21: Bagpipes | CH21: Lyre | CI21: Wardrums | CJ21: Guitar | CK21: Accordion | CL21: Cello | CM21: Violin | CN21: Harp | CO21: Summoning Seal | CP21: Hand Mirror | CQ21: Tomahawks | CR21: Planchette | CS21: Sagaris | CT21: Precipice Lance | CU21: Telescope | CV21: Lamp | CW21: Tentacles | CX21: Compact | CY21: Psalm | CZ21: Aspergillium | DA21: Thurible | DB21: Crosier | DC21: Absolution | DD21: Morningstar | DE21: Caduceus | DF21: Penitent | DG21: Requiem | DH21: Reliquary | DI21: Harpoon | DJ21: Guillotine Bow | DK21: Coffin Bow | DL21: Noose Strung Crossbow | DM21: Deathknell | DN21: Umbral Bow | DO21: Sandpouch | DP21: Ankou Bow | DQ21: Quietus | DR21: Smoke Lantern | DS21: Mindshard | DT21: Hovering Orbs | DU21: Crystallized Memory | DV21: Pendulum Chain | DW21: Crystal Ball | DX21: Ghostly Accompaniment | DY21: Axiom Rod | DZ21: Trepan | EA21: Hourglass | EB21: Marionette | EC21: Obelisk | ED21: Sign of Girru | EE21: Stone Rod | EF21: Sigil Staff | EG21: Unraveller | EH21: Quill Rod | EI21: Crook | EJ21: Glyph | EK21: Cypher | EL21: Arcanite | EM21: Ritual Dagger | EN21: Wormwood | EO21: Torch | EP21: Sickle | EQ21: Icicle | ER21: Seax | ES21: Wanga | ET21: Stang | EU21: Broom | EV21: Vervain | EW21: Elemental Staff | EX21: Dark Wand | EY21: Water Wand | EZ21: Earth Wand | FA21: Air Wand | FB21: Fire Wand | FC21: Aether Wand | FD21: Light Wand | FE21: Intonation | FF21: Staff of Power
