Workbook
Name _Hlk99922360: SubclassAspects!$BE$65

Sheet Sheet1
C1: Name: | D1: Scout
C2: Tier: | D2: 1
C3: Base: | D3: Archer
C4: Code: | D4: 2
C5: Requirements:
C6: =IF(SubclassAspects!C13>0,"Dexterity ", "") -> Dexterity | D6: =IF(SubclassAspects!C13>0,SubclassAspects!C13) -> 58 | E6: =IF(SubclassAspects!C17>0,"Charisma ", "") -> Charisma | F6: =IF(SubclassAspects!C17>0,SubclassAspects!C17, "") -> 58
C7: =IF(SubclassAspects!C14>0,"Dexterity ","") | D7: =IF(SubclassAspects!C14>0,SubclassAspects!C14, "") | E7: =IF(SubclassAspects!C18>0,"Endurance ", "") -> Endurance | F7: =IF(SubclassAspects!C18>0,SubclassAspects!C18, "") -> 53
C8: =IF(SubclassAspects!C15>0,"Strength ","") -> Strength | D8: =IF(SubclassAspects!C15>0,SubclassAspects!C15, "") -> 54 | E8: =IF(SubclassAspects!C19>0,"Luck ", "") | F8: =IF(SubclassAspects!C19>0,SubclassAspects!C19, "")
C9: =IF(SubclassAspects!C16>0,"Wisdom ","") -> Wisdom | D9: =IF(SubclassAspects!C16>0,SubclassAspects!C16, "") -> 61 | E9: =IF(SubclassAspects!C20>0,"Will ", "") -> Will | F9: =IF(SubclassAspects!C20>0,SubclassAspects!C20, "") -> 54
A11: Overview
A13: Quote: | B13: “With proper preparations, the fighting is merely a formality.”
A14: The Scout is an archer-based class that can act early and effectively. He uses preliminary actions to take control of the battlefield, attacks enemies at full health, and quickens himself readily. He is hard to destroy before his turn.
A15: World Notes: Scouts are an essential part of enemy army, as only with knowledge of the enemy can success be found. The scouts prepare the battlefield to best support their army’s success.
A16: Appearance: The scout is lightly armored because he is constantly on the move.
A17: Defining Mechanic: The Scout can implement scouted abilities. These abilities, which come in all three strengths, can only be used as the first action of battle, after which they turn into a related, but lesser, ability.
A19: Equipment
A20: Default Weapon: | C20: Short Bow
A21: Default Armor:
A41: Major Abilities
A42: Adroit Momentum – Ranged attack with pinpoint and momentum enhancing accuracy (Scout)
A43: Aimed Momentum – Ranged attack that generates extra aim based on momentum (Scout)
A44: Coordinated Shot – Ranged attack with quick preparation that grants increased accuracy and damage to next attack versus target (Scout)
A45: Delaying Jolt – Ranged attack with delay against stunned target (Scout)
A46: Flanking Shot – Ranged attack that causes flanked (Scout)
A47: Lay of the Land – Ranged attack that enhances dodge of team based on aim (Scout)
A48: Quickening Aim – Ranged attack against single target that consumes aim to quicken self (Scout)
A49: Rapid Vow – Prepared ranged attack that determines target on preparation. Quickens scout on preparation and on use (Scout)
A50: Scouted Arrow Burst – Ranged attack against all enemies. Deals less damage and requires aim if not first turn (Scout)
A51: Scouted Chink – Full penetration ranged attack if first attack of battle. Can proc full penetration with ranged attack after (Scout)
... A71: Share Momentum – Quicken all allies based on momentum (Scout)

Sheet SubclassAspects
D1: Hunter | P1: Wrestler | AO1: Siege Engineer | AV1: Rager | BR1: Black Knight | CD1: Sword Magus | EQ1: Winter Witch | ES1: Witch Doctor
A2: Name | B2: =COUNTA(C2:FF2)/1.6 -> 100 | C2: Scout | D2: Huntsman | E2: Crossbowman | F2: Marksman | G2: Falconer | H2: Bounty Hunter | I2: Stalker | J2: Poacher | K2: Sharpshooter | L2: Toxophilite | M2: Initiate | N2: Pugilist | O2: Skirmisher | P2: Vajra | Q2: Stonefist | R2: Infiltrator | S2: Viper Fang | T2: Ascetic | U2: Thunderfist | V2: Drunken Master | W2: Bandit | X2: Cutthroat | Y2: Burglar | Z2: Thief | AA2: Acrobat | AB2: Assassin | AC2: Brigand | AD2: Smuggler | AE2: Skulk | AF2: Ninja | AG2: Scavenger | AH2: Alchemist | AI2: Artificer | AJ2: Tinker | AK2: Engineer | AL2: Bomber | AM2: Gunslinger | AN2: Savant | AO2: Machinist | AP2: Reliquarian | AQ2: Brute | AR2: Raider | AS2: Berserker | AT2: Marauder | AU2: Viking | AV2: Vandal | AW2: Fury | AX2: Cannibal | AY2: Destroyer | AZ2: Beastlord | BA2: Gladiator | BB2: Duelist | BC2: Phalanx | BD2: Dervish | BE2: Fencer | BF2: Lancer | BG2: Samurai | BH2: Dreadnaught | BI2: Swashbuckler | BJ2: Warlord | BK2: Bodyguard | BL2: Champion | BM2: Hospitaler | BN2: Cavalier | BO2: Sentinel | BP2: Dragoon | BQ2: Paragon | BR2: Blackguard | BS2: Crusader | BT2: Templar | BU2: Blitzknecht | BV2: Feuerknecht | BW2: Trinknecht | BX2: Drecknecht | BY2: Mercenary | BZ2: Transmuter | CA2: Force Weaver | CB2: Myrmidon | CC2: Nightblade | CD2: Sword Saint | CE2: Minstrel | CF2: Jester | CG2: Dirge Singer | CH2: Balladeer | CI2: Drummer | CJ2: Spy | CK2: Mountebank | CL2: Diva | CM2: Muse | CN2: Lantern Bearer | CO2: Conjurer | CP2: Occultist | CQ2: Shaman | CR2: Medium | CS2: Animist | CT2: Spiritualist | CU2: Astrologer | CV2: Vizier | CW2: Alienist | CX2: Pact Master | CY2: Acolyte | CZ2: Healer | DA2: Disciple | DB2: Priest | DC2: Combat Medic | DD2: Exorcist | DE2: Preacher | DF2: Zealot | DG2: Plague Doctor | DH2: Oracle | DI2: Buccaneer | DJ2: Executioner | DK2: Gravedigger | DL2: Hangman | DM2: Harbinger | DN2: Sin Eater | DO2: Sandman | DP2: Whisperer | DQ2: Mercy Bringer | DR2: Gaslighter | DS2: Telepath | DT2: Kinetic | DU2: Amnesiac | DV2: Hypnotist | DW2: Diviner | DX2: Haunted | DY2: Mastermind | DZ2: Mindbleeder | EA2: Chronomancer | EB2: Puppet Master | EC2: Abjurer | ED2: Symbolist | EE2: Cabalist | EF2: Hermit | EG2: Disenchanter | EH2: Scrivener | EI2: Sage | EJ2: Glyphic | EK2: Cryptic | EL2: Sorcerer | EM2: Cultist | EN2: Warlock | EO2: Effigist | EP2: Dustbringer | EQ2: Crone | ER2: Hedgemage | ES2: Mambo | ET2: Bokor | EU2: Hag | EV2: Malefax | EW2: Elementalist | EX2: Necromancer | EY2: Hydromancer | EZ2: Geomancer | FA2: Aeromancer | FB2: Pyromancer | FC2: Arcanist | FD2: Solomancer | FE2: Incanter | FF2: Thaumaturge
A3: Code | B3: =COUNTA(C3:FF3)/1.6 -> 100 | C3: 2 | D3: 3 | E3: 4 | F3: 5 | G3: 6 | H3: 7 | I3: 8 | J3: 9 | K3: 10 | L3: 11 | M3: 13 | N3: 14 | O3: 15 | P3: 16 | Q3: 17 | R3: 18 | S3: 19 | T3: 20 | U3: 21 | V3: 22 | W3: 24 | X3: 25 | Y3: 26 | Z3: 27 | AA3: 28 | AB3: 29 | AC3: 30 | AD3: 31 | AE3: 32 | AF3: 33 | AG3: 35 | AH3: 36 | AI3: 37 | AJ3: 38 | AK3: 39 | AL3: 40 | AM3: 41 | AN3: 42 | AO3: 43 | AP3: 44 | AQ3: 46 | AR3: 47 | AS3: 48 | AT3: 49 | AU3: 50 | AV3: 51 | AW3: 52 | AX3: 53 | AY3: 54 | AZ3: 55 | BA3: 57 | BB3: 58 | BC3: 59 | BD3: 60 | BE3: 61 | BF3: 62 | BG3: 63 | BH3: 64 | BI3: 65 | BJ3: 66 | BK3: 68 | BL3: 69 | BM3: 70 | BN3: 71 | BO3: 72 | BP3: 73 | BQ3: 74 | BR3: 75 | BS3: 76 | BT3: 77 | BU3: 79 | BV3: 80 | BW3: 81 | BX3: 82 | BY3: 83 | BZ3: 84 | CA3: 85 | CB3: 86 | CC3: 87 | CD3: 88 | CE3: 90 | CF3: 91 | CG3: 92 | CH3: 93 | CI3: 94 | CJ3: 95 | CK3: 96 | CL3: 97 | CM3: 98 | CN3: 99 | CO3: 101 | CP3: 102 | CQ3: 103 | CR3: 104 | CS3: 105 | CT3: 106 | CU3: 107 | CV3: 108 | CW3: 109 | CX3: 110 | CY3: 112 | CZ3: 113 | DA3: 114 | DB3: 115 | DC3: 116 | DD3: 117 | DE3: 118 | DF3: 119 | DG3: 120 | DH3: 121 | DI3: 123 | DJ3: 124 | DK3: 125 | DL3: 126 | DM3: 127 | DN3: 128 | DO3: 129 | DP3: 130 | DQ3: 131 | DR3: 132 | DS3: 134 | DT3: 135 | DU3: 136 | DV3: 137 | DW3: 138 | DX3: 139 | DY3: 140 | DZ3: 141 | EA3: 142 | EB3: 143 | EC3: 145 | ED3: 146 | EE3: 147 | EF3: 148 | EG3: 149 | EH3: 150 | EI3: 151 | EJ3: 152 | EK3: 153 | EL3: 154 | EM3: 156 | EN3: 157 | EO3: 158 | EP3: 159 | EQ3: 160 | ER3: 161 | ES3: 162 | ET3: 163 | EU3: 164 | EV3: 165 | EW3: 167 | EX3: 168 | EY3: 169 | EZ3: 170 | FA3: 171 | FB3: 172 | FC3: 173 | FD3: 174 | FE3: 175 | FF3: 176
A4: Tier | B4: =COUNTA(C4:FF4)/1.6 -> 100 | C4: 1 | D4: 2 | E4: 6 | F4: 7 | G4: 9 | H4: 13 | I4: 15 | J4: 19 | K4: 21 | L4: 25 | M4: 1 | N4: 2 | O4: 6 | P4: 7 | Q4: 9 | R4: 13 | S4: 15 | T4: 19 | U4: 21 | V4: 25 | W4: 1 | X4: 2 | Y4: 6 | Z4: 7 | AA4: 9 | AB4: 13 | AC4: 15 | AD4: 19 | AE4: 21 | AF4: 25 | AG4: 1 | AH4: 2 | AI4: 6 | AJ4: 7 | AK4: 9 | AL4: 13 | AM4: 15 | AN4: 19 | AO4: 21 | AP4: 25 | AQ4: 1 | AR4: 2 | AS4: 6 | AT4: 7 | AU4: 9 | AV4: 13 | AW4: 15 | AX4: 19 | AY4: 21 | AZ4: 25 | BA4: 1 | BB4: 2 | BC4: 6 | BD4: 7 | BE4: 9 | BF4: 13 | BG4: 15 | BH4: 19 | BI4: 21 | BJ4: 25 | BK4: 1 | BL4: 2 | BM4: 6 | BN4: 7 | BO4: 9 | BP4: 13 | BQ4: 15 | BR4: 19 | BS4: 21 | BT4: 25 | BU4: 1 | BV4: 2 | BW4: 6 | BX4: 7 | BY4: 9 | BZ4: 13 | CA4: 15 | CB4: 19 | CC4: 21 | CD4: 25 | CE4: 1 | CF4: 2 | CG4: 6 | CH4: 7 | CI4: 9 | CJ4: 13 | CK4: 15 | CL4: 19 | CM4: 21 | CN4: 25 | CO4: 1 | CP4: 2 | CQ4: 6 | CR4: 7 | CS4: 9 | CT4: 13 | CU4: 15 | CV4: 19 | CW4: 21 | CX4: 25 | CY4: 1 | CZ4: 2 | DA4: 6 | DB4: 7 | DC4: 9 | DD4: 13 | DE4: 15 | DF4: 19 | DG4: 21 | DH4: 25 | DI4: 1 | DJ4: 2 | DK4: 6 | DL4: 7 | DM4: 9 | DN4: 13 | DO4: 15 | DP4: 19 | DQ4: 21 | DR4: 25 | DS4: 1 | DT4: 2 | DU4: 6 | DV4: 7 | DW4: 9 | DX4: 13 | DY4: 15 | DZ4: 19 | EA4: 21 | EB4: 25 | EC4: 1 | ED4: 2 | EE4: 6 | EF4: 7 | EG4: 9 | EH4: 13 | EI4: 15 | EJ4: 19 | EK4: 21 | EL4: 25 | EM4: 1 | EN4: 2 | EO4: 6 | EP4: 7 | EQ4: 9 | ER4: 13 | ES4: 15 | ET4: 19 | EU4: 21 | EV4: 25 | EW4: 1 | EX4: 2 | EY4: 6 | EZ4: 7 | FA4: 9 | FB4: 13 | FC4: 15 | FD4: 19 | FE4: 21 | FF4: 25
A5: Base Class | B5: =COUNTA(C5:FF5)/1.6 -> 100 | C5: Archer | D5: Archer | E5: Archer | F5: Archer | G5: Archer | H5: Archer | I5: Archer | J5: Archer | K5: Archer | L5: Archer | M5: Monk | N5: Monk | O5: Monk | P5: Monk | Q5: Monk | R5: Monk | S5: Monk | T5: Monk | U5: Monk | V5: Monk | W5: Rogue | X5: Rogue | Y5: Rogue | Z5: Rogue | AA5: Rogue | AB5: Rogue | AC5: Rogue | AD5: Rogue | AE5: Rogue | AF5: Rogue | AG5: Teknixian | AH5: Teknixian | AI5: Teknixian | AJ5: Teknixian | AK5: Teknixian | AL5: Teknixian | AM5: Teknixian | AN5: Teknixian | AO5: Teknixian | AP5: Teknixian | AQ5: Barbarian | AR5: Barbarian | AS5: Barbarian | AT5: Barbarian | AU5: Barbarian | AV5: Barbarian | AW5: Barbarian | AX5: Barbarian | AY5: Barbarian | AZ5: Barbarian | BA5: Fighter | BB5: Fighter | BC5: Fighter | BD5: Fighter | BE5: Fighter | BF5: Fighter | BG5: Fighter | BH5: Fighter | BI5: Fighter | BJ5: Fighter | BK5: Knight | BL5: Knight | BM5: Knight | BN5: Knight | BO5: Knight | BP5: Knight | BQ5: Knight | BR5: Knight | BS5: Knight | BT5: Knight | BU5: Spellsword | BV5: Spellsword | BW5: Spellsword | BX5: Spellsword | BY5: Spellsword | BZ5: Spellsword | CA5: Spellsword | CB5: Spellsword | CC5: Spellsword | CD5: Spellsword | CE5: Bard | CF5: Bard | CG5: Bard | CH5: Bard | CI5: Bard | CJ5: Bard | CK5: Bard | CL5: Bard | CM5: Bard | CN5: Bard | CO5: Binder | CP5: Binder | CQ5: Binder | CR5: Binder | CS5: Binder | CT5: Binder | CU5: Binder | CV5: Binder | CW5: Binder | CX5: Binder | CY5: Cleric | CZ5: Cleric | DA5: Cleric | DB5: Cleric | DC5: Cleric | DD5: Cleric | DE5: Cleric | DF5: Cleric | DG5: Cleric | DH5: Cleric | DI5: Reaper | DJ5: Reaper | DK5: Reaper | DL5: Reaper | DM5: Reaper | DN5: Reaper | DO5: Reaper | DP5: Reaper | DQ5: Reaper | DR5: Reaper | DS5: Psychic | DT5: Psychic | DU5: Psychic | DV5: Psychic | DW5: Psychic | DX5: Psychic | DY5: Psychic | DZ5: Psychic | EA5: Psychic | EB5: Psychic | EC5: Runemage | ED5: Runemage | EE5: Runemage | EF5: Runemage | EG5: Runemage | EH5: Runemage | EI5: Runemage | EJ5: Runemage | EK5: Runemage | EL5: Runemage | EM5: Witch | EN5: Witch | EO5: Witch | EP5: Witch | EQ5: Witch | ER5: Witch | ES5: Witch | ET5: Witch | EU5: Witch | EV5: Witch | EW5: Wizard | EX5: Wizard | EY5: Wizard | EZ5: Wizard | FA5: Wizard | FB5: Wizard | FC5: Wizard | FD5: Wizard | FE5: Wizard | FF5: Wizard
A6: Gender | B6: =COUNTA(C6:FF6)/1.6 -> 100 | C6: Male | D6: Male | E6: Male | F6: Male | G6: Male | H6: Male | I6: Male | J6: Male | K6: Male | L6: Male | M6: Male | N6: Male | O6: Male | P6: Male | Q6: Male | R6: Male | S6: Male | T6: Male | U6: Male | V6: Male | W6: Male | X6: Male | Y6: Male | Z6: Male | AA6: Male | AB6: Male | AC6: Male | AD6: Male | AE6: Male | AF6: Male | AG6: Female | AH6: Female | AI6: Female | AJ6: Female | AK6: Female | AL6: Female | AM6: Female | AN6: Female | AO6: Female | AP6: Female | AQ6: Female | AR6: Female | AS6: Female | AT6: Female | AU6: Female | AV6: Female | AW6: Female | AX6: Female | AY6: Female | AZ6: Female | BA6: Female | BB6: Female | BC6: Female | BD6: Female | BE6: Female | BF6: Female | BG6: Female | BH6: Female | BI6: Female | BJ6: Female | BK6: Male | BL6: Male | BM6: Male | BN6: Male | BO6: Male | BP6: Male | BQ6: Male | BR6: Male | BS6: Male | BT6: Male | BU6: Female | BV6: Female | BW6: Female | BX6: Female | BY6: Female | BZ6: Female | CA6: Female | CB6: Female | CC6: Female | CD6: Female | CE6: Male | CF6: Male | CG6: Male | CH6: Male | CI6: Male | CJ6: Male | CK6: Male | CL6: Male | CM6: Male | CN6: Male | CO6: Female | CP6: Female | CQ6: Female | CR6: Female | CS6: Female | CT6: Female | CU6: Female | CV6: Female | CW6: Female | CX6: Female | CY6: Male | CZ6: Male | DA6: Male | DB6: Male | DC6: Male | DD6: Male | DE6: Male | DF6: Male | DG6: Male | DH6: Male | DI6: Male | DJ6: Male | DK6: Male | DL6: Male | DM6: Male | DN6: Male | DO6: Male | DP6: Male | DQ6: Male | DR6: Male | DS6: Female | DT6: Female | DU6: Female | DV6: Female | DW6: Female | DX6: Female | DY6: Female | DZ6: Female | EA6: Female | EB6: Female | EC6: Male | ED6: Male | EE6: Male | EF6: Male | EG6: Male | EH6: Male | EI6: Male | EJ6: Male | EK6: Male | EL6: Male | EM6: Female | EN6: Female | EO6: Female | EP6: Female | EQ6: Female | ER6: Female | ES6: Female | ET6: Female | EU6: Female | EV6: Female | EW6: Female | EX6: Female | EY6: Female | EZ6: Female | FA6: Female | FB6: Female | FC6: Female | FD6: Female | FE6: Female | FF6: Female
A7: Associated Demon | B7: =COUNTA(C7:FF7)/1.6 -> 36.875 | C7: Ipos | D7: Leraje | E7: Dantalion | F7: Allocer | G7: Pazazu | H7: Baphomet | I7: Demogorgon | J7: Set | K7: Glasya | L7: Andras | M7: Glasya | N7: Gusion | O7: Pazazu | P7: Andras | Q7: Scarmiglione | R7: Sabnock | S7: Orobas | T7: Levistus | U7: Paimon | V7: Gaap | W7: Ipos | X7: Geryon | Y7: Mammon | Z7: Sabnock | AA7: Bifrons | AB7: Glasya | AC7: Gusion | AD7: Orobas | AE7: Andras | AF7: x | AG7: Belial | AH7: Haagenti | AI7: x | AJ7: Mammon | AK7: Orobas | AL7: Tiamat | AM7: Leraje | AN7: Orcus | AO7: Rubicante | AP7: Eligos | AQ7: x | AR7: Dagon | AS7: Gaap | AT7: Demogorgon | AU7: Focalor | AV7: Murmur | AW7: Allocer | AX7: Andras | AY7: Demogorgon | AZ7: Gusion | BA7: Ipos | BB7: Sabnock | BC7: Levistus | BD7: Agares | BE7: Succor-Benoth | BF7: Paimon | BG7: Marchosias | BH7: Dispater | BI7: Focalor
A8: Quote | B8: =COUNTA(C8:FF8)/1.6 -> 9.375 | D8: “A person can turn from predator to prey in just an instant.” | E8: “It’s a simple enough device to use even you should be able to handle it.” | H8: “There’s a bounty for your head. Not sure about the rest of your body.” | M8: “This is what all my training has led to.” | Q8: “Be like the stone, unbreakable, unyielding.” | R8: “Get in. Get the job done. Get out. Don’t get spotted.” | U8: “I strike like lightning, and thunder follows.” | V8: “One more drink and I’ll get to it.” | AQ8: “It’s simple. I am the brute squad.” | AX8: “You look absolutely delicious.” | AY8: “Sometimes to save what we love, we must destroy everything.” | AZ8: “I am the lord of all beasts who walk the earth. They bow before me.” | BA8: “I’ve always wanted to compete in the big show.” | BG8: “Is there no honor in how you fight?” | BH8: “There’s no stopping me now.”
